Workbook

Sheet README
A1: Competitive Product Catalog: Wave 1 (Women's Tights)
A2: Consello internal working file. Uses lululemon's internal category names (no plan figures). Do not share outside the deal team.
A4: Purpose | B4: One product structure for Alo, lululemon, Vuori, Athleta and Beyond Yoga, mapped to lululemon's own division, class and subclass names, so competitor assortment can be compared directly against internal plan and actuals.
A5: Wave 1 scope | B5: Women's Tights (leggings and capris). Biker shorts go to Shorts in a later wave. Leggings sold only inside a set are still captured as single items.
A6: Unit of count | B6: One row per style-color. A style is brand + brand_style_code. Length variants (lululemon *Regular / *Short / *Tall) are one style with length_variant recorded, so lululemon's style count is not inflated. Vuori and Beyond Yoga publish one web address per color; the crawler collapses these on brand_style_code.
A7: Pricing rule | B7: Always store list_price and selling_price separately, plus capture_date and any sitewide promotion text. Athleta was running 30% off everything (Friends & Family) on 30 Sep 2026, so Athleta selling prices captured that week are promotional.
A8: Done test | B8: Wave 1 is done when every brand clears 90% fill on the required fields (QA_Checks tab) AND the style count reconciles to within 5% of the brand's own leggings category count.
A9: Tabs | B9: Field_Dictionary: every column, definition, allowed values, how it is extracted. Taxonomy_Map: lululemon class to each brand's category name and URL. Overlap_Matrix: which brands sell each class, plus depth test once counts come in. Fabric_Normalization: proprietary fabric and line names to fiber and properties. Wave1_Catalog: crawler output lands here (one example row). QA_Checks: fill rate and reconciliation by brand. Source_Log: platform, URL patterns and collection notes per site.
A10: Color legend | B10: Blue text = typed-in value. Black = formula. Green = pulls from another tab. Yellow fill = input you should fill in or confirm.
A11: Data source | B11: Public websites only, for all five brands including lululemon. No client internal data feeds the catalog. Expect errors in fields sites don't state plainly (franchise, activity, core vs seasonal). Those fields carry extraction_method so reviewers know what to check.
A12: Collection practice | B12: Crawler respects robots.txt, runs one request every 3 seconds per site, uses no logins, and stores raw pages for audit. Scope set by engagement lead, 30 Sep 2026.

Sheet Field_Dictionary
A1: # | B1: Field | C1: Group | D1: Definition | E1: Type / format | F1: Allowed values | G1: Where it comes from | H1: Extraction | I1: Required W1 | J1: Example (Vuori FormRefined Legging, 30 Sep 2026)
A2: 1 | B2: capture_date | C2: Identity | D2: Date the page was collected | E2: YYYY-MM-DD | G2: Crawler clock | H2: Auto | I2: Y | J2: 2026-09-30
A3: 2 | B3: brand | C3: Identity | D3: Brand name | E3: Text | F3: Alo; lululemon; Vuori; Athleta; Beyond Yoga | G3: Config | H3: Auto | I3: Y | J3: Vuori
A4: 3 | B4: source_url | C4: Identity | D4: Product page address as collected | E4: URL | G4: Category page crawl | H4: Auto | I4: Y | J4: https://vuoriclothing.com/products/womens-formrefined-legging-french-roast
A5: 4 | B5: brand_style_code | C5: Identity | D5: Brand's own style number, without color suffix | E5: Text | G5: Product data, image file names, SKU prefix | H5: Structured | I5: Y | J5: VW4494
A6: 5 | B6: style_group_key | C6: Identity | D6: Key used to count styles. Equals brand_style_code, except lululemon, where it is the style name with the length suffix removed | E6: Text | G6: Built by crawler | H6: Auto | I6: Y | J6: vuori|vw4494
A7: 6 | B7: style_name | C7: Identity | D7: Product name as shown | E7: Text | G7: Page title / product data | H7: Structured | I7: Y | J7: FormRefined Legging
A8: 7 | B8: color_name | C8: Identity | D8: Brand color name | E8: Text | G8: Variant option | H8: Structured | I8: Y | J8: French Roast
A9: 8 | B9: style_color_id | C9: Identity | D9: brand|brand_style_code|color_name, lowercased | E9: Text | F9: Unique key | G9: Built by crawler | H9: Auto | I9: Y | J9: vuori|vw4494|french roast
A10: 9 | B10: length_variant | C10: Identity | D10: Length version of the same style | E10: Text | F10: Regular; Short; Tall; Petite; n/a | G10: Name suffix or option | H10: Rule | I10: N | J10: n/a
A11: 10 | B11: gender | C11: Identity | D11: Gender merchandised | E11: Text | F11: Women; Men; Unisex; Girls | G11: Category page | H11: Auto | I11: Y | J11: Women
A12: 11 | B12: brand_category_path | C12: Taxonomy | D12: Brand's own category where the item was found | E12: Text | G12: Category page crawl | H12: Auto | I12: Y | J12: Women > Leggings
A13: 12 | B13: lulu_division | C13: Taxonomy | D13: lululemon division | E13: Text | F13: lulu Womens; lulu Mens; lulu Accessories; lulu Footwear | G13: Taxonomy_Map rule | H13: Rule | I13: Y | J13: lulu Womens
A14: 13 | B14: lulu_class | C14: Taxonomy | D14: lululemon class | E14: Text | F14: See Taxonomy_Map | G14: Taxonomy_Map rule | H14: Rule | I14: Y | J14: Womens Pants
A15: 14 | B15: lulu_subclass | C15: Taxonomy | D15: lululemon subclass | E15: Text | F15: See Taxonomy_Map | G15: Taxonomy_Map rule | H15: Rule | I15: Y | J15: Womens Tights
A16: 15 | B16: activity | C16: Taxonomy | D16: Primary activity, mapped to lululemon's list | E16: Text | F16: Yoga; Train; Run; Tennis; Golf; Lounge; Social; Sweatlife; Recovery; Hike; Swim; Travel; Unassigned | G16: Brand activity tags and copy | H16: LLM + review | I16: N | J16: Unassigned
A17: 16 | B17: brand_line | C17: Taxonomy | D17: Brand franchise or product line | E17: Text | G17: Name, collection tags | H17: LLM + review | I17: Y | J17: FormRefined
A18: 17 | B18: list_price_usd | C18: Commercial | D18: Full (not reduced) price | E18: Number, USD | G18: Compare-at or original price | H18: Structured | I18: Y | J18: 118
A19: 18 | B19: selling_price_usd | C19: Commercial | D19: Price a shopper pays that day | E19: Number, USD | G19: Current price | H19: Structured | I19: Y | J19: 118
A20: 19 | B20: markdown_pct | C20: Commercial | D20: 1 minus selling / list | E20: Fraction | F20: 0 to 1 | G20: Calculated | H20: Formula | I20: Y | J20: 0
A21: 20 | B21: on_promo_flag | C21: Commercial | D21: Selling price below list, or a sitewide promotion is live | E21: Y/N | F21: Y; N | G21: Price fields, promo banner | H21: Rule | I21: Y | J21: N
A22: 21 | B22: sitewide_promo_text | C22: Commercial | D22: Promotion banner text on capture date | E22: Text | G22: Homepage banner | H22: Auto | I22: N
A23: 22 | B23: is_new_flag | C23: Commercial | D23: Marked New / New Arrival | E23: Y/N | F23: Y; N | G23: Badge, tags | H23: Structured | I23: Y | J23: Y
A24: 23 | B24: size_range | C24: Size | D24: Smallest to largest size offered | E24: Text | G24: Size options | H24: Structured | I24: Y | J24: XXS-XXL
A25: 24 | B25: size_count | C25: Size | D25: Number of sizes offered | E25: Integer | G25: Size options | H25: Structured | I25: Y | J25: 7
A26: 25 | B26: sizes_available | C26: Size | D26: Sizes in stock at capture | E26: Text list | G26: Variant availability | H26: Structured | I26: Y | J26: (captured by crawler)
A27: 26 | B27: sizes_out_of_stock | C27: Size | D27: Sizes sold out at capture | E27: Text list | G27: Variant availability | H27: Structured | I27: Y | J27: (captured by crawler)
A28: 27 | B28: extended_size_flag | C28: Size | D28: Offers above XL or above size 14 | E28: Y/N | F28: Y; N | G28: Size options | H28: Rule | I28: Y | J28: Y
A29: 28 | B29: inseam_in | C29: Fit | D29: Inseam in inches, if stated | E29: Number | G29: Name, fit copy | H29: Regex | I29: N
A30: 29 | B30: rise | C30: Fit | D30: Rise as stated | E30: Text | F30: Low; Mid; High; Super High; Not stated | G30: Fit copy | H30: Regex | I30: Y | J30: High
A31: 30 | B31: length_descriptor | C31: Fit | D31: Length as stated | E31: Text | F31: Full; 7/8; Ankle; Capri; Flare; Not stated | G31: Fit copy, name | H31: Regex | I31: Y | J31: Ankle
A32: 31 | B32: fit_descriptor | C32: Fit | D32: Fit as stated | E32: Text | F32: Tight; Stretch to fit; Relaxed; Flare; Not stated | G32: Fit copy | H32: Regex | I32: Y | J32: Stretch to fit
A33: 32 | B33: waistband_type | C33: Construction | D33: Waistband build | E33: Text | F33: Bonded; Seamless; Folded; Elastic; Drawcord; V-front; Not stated | G33: Features copy | H33: LLM + review | I33: N | J33: Bonded
A34: 33 | B34: pockets | C34: Construction | D34: Pocket description | E34: Text | F34: None; Side drop-in; Waistband; Hidden; Not stated | G34: Features copy | H34: LLM + review | I34: Y | J34: Not stated
A35: 34 | B35: front_seam | C35: Construction | D35: Front rise seam | E35: Text | F35: Yes; No; Not stated | G35: Features copy | H35: Regex | I35: N | J35: No
A36: 35 | B36: fabric_platform | C36: Material | D36: Brand fabric name | E36: Text | F36: See Fabric_Normalization | G36: Name, fabric copy | H36: LLM + review | I36: Y | J36: Vuori BlissBlend Form
A37: 36 | B37: fiber_content_raw | C37: Material | D37: Fiber content exactly as printed | E37: Text | G37: Fabric & care section | H37: Regex | I37: Y | J37: 74% Polyamide, 26% Elastane (Shell), 88% Polyester, 12% Elastane (Liner)
A38: 37 | B38: primary_fiber | C38: Material | D38: Largest fiber in main body (shell) | E38: Text | F38: Nylon/Polyamide; Polyester; Cotton; Lyocell; Modal; Wool; Other | G38: Parsed from raw | H38: Rule | I38: Y | J38: Nylon/Polyamide
A39: 38 | B39: primary_fiber_pct | C39: Material | D39: Share of primary fiber in shell | E39: Fraction | F39: 0 to 1 | G39: Parsed from raw | H39: Rule | I39: Y | J39: 0.74
A40: 39 | B40: elastane_pct | C40: Material | D40: Elastane / spandex / Lycra share in shell | E40: Fraction | F40: 0 to 1 | G40: Parsed from raw | H40: Rule | I40: Y | J40: 0.26
...

Sheet Taxonomy_Map
A1: lulu_division | B1: lulu_class | C1: lulu_subclass | D1: Wave | E1: Alo category | F1: lululemon category | G1: Vuori category | H1: Athleta category | I1: Beyond Yoga category | J1: Mapping rule / notes
A2: lulu Womens | B2: Womens Pants | C2: Womens Tights | D2: 1 | E2: Leggings /collections/womens-leggings | F2: Leggings /c/women-leggings/n1udsq; Capris /c/women-capris/n1ml6n | G2: Women's Leggings /collections/womens-leggings | H2: Bottoms cid=1025878 (leggings subcategory to confirm on first run) | I2: Leggings /collections/leggings; Capris + Pedal Pushers /collections/pedal-pushers-capris | J2: Includes leggings, tights, capris. Beyond Yoga 'Leggings with Pockets' is a subset of Leggings: de-duplicate on style_color_id. Biker shorts go to Womens Shorts.
A3: lulu Womens | B3: Womens Pants | C3: Womens Non-Tights | D3: 3 | E3: Pants & Trousers; Sweatpants | F3: Pants; Joggers; Sweatpants; Trousers | G3: Pants & Trousers; Joggers & Sweatpants; Denim | H3: Bottoms (subcategory to confirm) | I3: Pants; Bootcut + Wide Leg; Joggers + Sweatpants | J3: Denim is Vuori only today: tag it so it can be split out.
A4: lulu Womens | B4: Womens Bras | C4: Womens Sportsbras | D4: 2 | E4: Sports Bras | F4: Sports Bras | G4: Women's Sports Bras | H4: Bras | I4: Bras | J4: Capture support level (light / medium / high) as stated.
A5: lulu Womens | B5: Womens Bras | C5: Womens Intimates | D5: 5 | E5: Intimates | F5: Underwear | G5: Not found | H5: To confirm | I5: Not found | J5: Low overlap.
A6: lulu Womens | B6: Womens Tanks | C6: Womens Tanks | D6: 2 | E6: Tops | F6: Tank Tops | G6: Women's Tank Tops | H6: Tops (subcategory to confirm) | I6: Tanks; Crop Tanks
A7: lulu Womens | B7: Womens Tanks | C7: Womens Onesies/Dresses | D7: 3 | E7: Dresses; Onesies | F7: Dresses | G7: Women's Dresses & Jumpsuits | H7: Dresses | I7: Dresses; Active Dresses; Jumpsuits
A8: lulu Womens | B8: Womens SS-LS Tops | C8: Womens SS Tops | D8: 2 | E8: Tops | F8: T-Shirts; Shirts | G8: Women's Short Sleeve Tops; T-Shirts | H8: Tops (subcategory to confirm) | I8: Short Sleeve Tops
A9: lulu Womens | B9: Womens SS-LS Tops | C9: Womens LS Tops | D9: 2 | E9: Tops | F9: Long Sleeve Shirts | G9: Women's Long Sleeve Tops | H9: Tops (subcategory to confirm) | I9: Long Sleeve Tops
A10: lulu Womens | B10: Womens 2nd Layers | C10: Womens Pull-Overs | D10: 3 | E10: Sweatshirts & Hoodies; Sweaters & Knitwear | F10: Hoodies & Sweatshirts | G10: Women's Hoodies & Sweatshirts; Sweaters | H10: Tops (subcategory to confirm) | I10: Sweatshirts; Sweaters; Layers | J10: Split pull-over vs zip-up on name ('zip', 'full-zip', 'half-zip').
A11: lulu Womens | B11: Womens 2nd Layers | C11: Womens Zip-Ups | D11: 3 | E11: Sweatshirts & Hoodies | F11: Hoodies & Sweatshirts | G11: Women's Hoodies & Sweatshirts | H11: Jackets | I11: Sweatshirts + Hoodies | J11: Same rule as above.
A12: lulu Womens | B12: Womens Outerwear | C12: Womens Light / Heavy / Vests | D12: 3 | E12: Jackets & Coats | F12: Coats & Jackets; Vests | G12: Women's Jackets & Vests | H12: Jackets | I12: Outerwear + Jackets | J12: Heavy = insulated or down; Light = everything else.
A13: lulu Womens | B13: Womens Shorts/Skirts | C13: Womens Shorts / Skirts | D13: 3 | E13: Shorts; Skirts | F13: Shorts; Skirts | G13: Women's Shorts; Skirts | H13: Bottoms (subcategory to confirm) | I13: Shorts; Skirts | J13: Late-September capture understates this class. Plan a spring re-capture.
A14: lulu Womens | B14: Womens Underwear | C14: Womens Underwear | D14: 5 | E14: Intimates | F14: Underwear | G14: Not found | H14: To confirm | I14: Not found
A15: lulu Mens | B15: Mens Shorts | C15: Mens Fixed / Pull On | D15: 4 | E15: Shorts | F15: Shorts | G15: Men's Shorts | H15: Not sold | I15: Shorts | J15: Athleta does not sell Men's. Max overlap 4 of 5.
A16: lulu Mens | B16: Mens Pants | C16: Mens Pull On / Fixed / Tight | D16: 4 | E16: Pants; Sweatpants | F16: Pants; Joggers; 5 Pocket; Dress Pants; Trousers | G16: Men's Pants; Joggers; Denim; Chinos | H16: Not sold | I16: Pants; Joggers + Sweatpants | J16: Fixed = fixed waist (chino, 5-pocket, trouser).
A17: lulu Mens | B17: Mens SS-LS Tops | C17: Mens SS / LS / Tanks | D17: 4 | E17: Shirts | F17: T-Shirts; Long Sleeve; Polo; Button Down; Tank Tops | G17: Short Sleeve; Long Sleeve; Polos; Button Downs; Tanks | H17: Not sold | I17: Tanks + Tees; Long Sleeves
A18: lulu Mens | B18: Mens 2nd Layers | C18: Mens Pull-Overs / Zip-Ups | D18: 4 | E18: Sweatshirts & Hoodies | F18: Hoodies & Sweatshirts; Quarter Zips | G18: Men's Hoodies and Sweatshirts; Sweaters | H18: Not sold | I18: Hoodies + Sweatshirts
A19: lulu Mens | B19: Mens Outerwear | C19: Mens Light / Heavy / Vests | D19: 4 | E19: Jackets | F19: Coats & Jackets; Vests | G19: Men's Jackets & Vests | H19: Not sold | I19: Jackets + Vests
A20: lulu Mens | B20: Mens Underwear | C20: Mens Underwear | D20: 5 | E20: Boxers | F20: Underwear | G20: Men's Underwear | H20: Not sold | I20: Not found
A21: lulu Footwear | B21: Womens / Mens Footwear | C21: Performance / OTM | D21: 5 | E21: Sneakers; Slides | F21: Shoes | G21: Shoes | H21: To confirm | I21: Not found
A22: lulu Accessories | B22: Bags; Equipment; Headwear; Socks | D22: 5 | E22: Bags; Mats; Hats; Socks | F22: Bags; Equipment; Hats; Socks | G22: Bags; Equipment; Hats; Socks | H22: Accessories | I22: Accessories
A23: Not in lululemon hierarchy | B23: White space | D23: 5 | E23: Wellness (hair, skin, body, home, supplements) | G23: Swim; Denim; Cashmere; Snow | H23: Athleta Girl | I23: Maternity; Toddler; Extended 1X-4X | J23: Categories with no lululemon class. Map these for the white-space view.
A25: Source: lululemon class/subclass names from PADS4914 plan file (names only). Brand categories from each site's navigation, captured 30 Sep 2026.

Sheet Overlap_Matrix
A1: Category overlap and depth test
A2: Presence codes: Y = confirmed on site navigation, P = parent category exists, subcategory not yet confirmed, N = not sold. Style-color counts fill in after each crawl.
A3: Depth threshold (style-colors per brand to count as real overlap) | F3: 15 | G3: Placeholder. Reset after Wave 1 counts are in.
A5: Category (lululemon class / subclass) | B5: Wave | C5: Alo | D5: lululemon | E5: Vuori | F5: Athleta | G5: Beyond Yoga | H5: Brands present (Y+P) | I5: Alo count | J5: lululemon count | K5: Vuori count | L5: Athleta count | M5: Beyond Yoga count | N5: Brands at depth | O5: Overlap call
A6: W Pants: Tights | B6: 1 | C6: Y | D6: Y | E6: Y | F6: P | G6: Y | H6: =COUNTIF(C6:G6,"Y")+COUNTIF(C6:G6,"P") -> 5 | N6: =IF(COUNT(I6:M6)=0,"",COUNTIF(I6:M6,">="&$F$3)) | O6: =IF(N6="",IF(H6>=5,"Full presence, depth pending",IF(H6=4,"4 of 5, depth pending","Low overlap")),IF(N6>=4,"Real overlap",IF(N6>=2,"Partial overlap","Low overlap"))) -> Full presence, depth pending
A7: W Pants: Non-Tights | B7: 3 | C7: Y | D7: Y | E7: Y | F7: P | G7: Y | H7: =COUNTIF(C7:G7,"Y")+COUNTIF(C7:G7,"P") -> 5 | N7: =IF(COUNT(I7:M7)=0,"",COUNTIF(I7:M7,">="&$F$3)) | O7: =IF(N7="",IF(H7>=5,"Full presence, depth pending",IF(H7=4,"4 of 5, depth pending","Low overlap")),IF(N7>=4,"Real overlap",IF(N7>=2,"Partial overlap","Low overlap"))) -> Full presence, depth pending
A8: W Bras: Sports bras | B8: 2 | C8: Y | D8: Y | E8: Y | F8: Y | G8: Y | H8: =COUNTIF(C8:G8,"Y")+COUNTIF(C8:G8,"P") -> 5 | N8: =IF(COUNT(I8:M8)=0,"",COUNTIF(I8:M8,">="&$F$3)) | O8: =IF(N8="",IF(H8>=5,"Full presence, depth pending",IF(H8=4,"4 of 5, depth pending","Low overlap")),IF(N8>=4,"Real overlap",IF(N8>=2,"Partial overlap","Low overlap"))) -> Full presence, depth pending
A9: W Tanks | B9: 2 | C9: Y | D9: Y | E9: Y | F9: P | G9: Y | H9: =COUNTIF(C9:G9,"Y")+COUNTIF(C9:G9,"P") -> 5 | N9: =IF(COUNT(I9:M9)=0,"",COUNTIF(I9:M9,">="&$F$3)) | O9: =IF(N9="",IF(H9>=5,"Full presence, depth pending",IF(H9=4,"4 of 5, depth pending","Low overlap")),IF(N9>=4,"Real overlap",IF(N9>=2,"Partial overlap","Low overlap"))) -> Full presence, depth pending
A10: W SS / LS Tops | B10: 2 | C10: Y | D10: Y | E10: Y | F10: P | G10: Y | H10: =COUNTIF(C10:G10,"Y")+COUNTIF(C10:G10,"P") -> 5 | N10: =IF(COUNT(I10:M10)=0,"",COUNTIF(I10:M10,">="&$F$3)) | O10: =IF(N10="",IF(H10>=5,"Full presence, depth pending",IF(H10=4,"4 of 5, depth pending","Low overlap")),IF(N10>=4,"Real overlap",IF(N10>=2,"Partial overlap","Low overlap"))) -> Full presence, depth pending
A11: W 2nd Layers | B11: 3 | C11: Y | D11: Y | E11: Y | F11: P | G11: Y | H11: =COUNTIF(C11:G11,"Y")+COUNTIF(C11:G11,"P") -> 5 | N11: =IF(COUNT(I11:M11)=0,"",COUNTIF(I11:M11,">="&$F$3)) | O11: =IF(N11="",IF(H11>=5,"Full presence, depth pending",IF(H11=4,"4 of 5, depth pending","Low overlap")),IF(N11>=4,"Real overlap",IF(N11>=2,"Partial overlap","Low overlap"))) -> Full presence, depth pending
A12: W Outerwear | B12: 3 | C12: Y | D12: Y | E12: Y | F12: Y | G12: Y | H12: =COUNTIF(C12:G12,"Y")+COUNTIF(C12:G12,"P") -> 5 | N12: =IF(COUNT(I12:M12)=0,"",COUNTIF(I12:M12,">="&$F$3)) | O12: =IF(N12="",IF(H12>=5,"Full presence, depth pending",IF(H12=4,"4 of 5, depth pending","Low overlap")),IF(N12>=4,"Real overlap",IF(N12>=2,"Partial overlap","Low overlap"))) -> Full presence, depth pending
A13: W Shorts / Skirts | B13: 3 | C13: Y | D13: Y | E13: Y | F13: P | G13: Y | H13: =COUNTIF(C13:G13,"Y")+COUNTIF(C13:G13,"P") -> 5 | N13: =IF(COUNT(I13:M13)=0,"",COUNTIF(I13:M13,">="&$F$3)) | O13: =IF(N13="",IF(H13>=5,"Full presence, depth pending",IF(H13=4,"4 of 5, depth pending","Low overlap")),IF(N13>=4,"Real overlap",IF(N13>=2,"Partial overlap","Low overlap"))) -> Full presence, depth pending
A14: W Onesies / Dresses | B14: 3 | C14: Y | D14: Y | E14: Y | F14: Y | G14: Y | H14: =COUNTIF(C14:G14,"Y")+COUNTIF(C14:G14,"P") -> 5 | N14: =IF(COUNT(I14:M14)=0,"",COUNTIF(I14:M14,">="&$F$3)) | O14: =IF(N14="",IF(H14>=5,"Full presence, depth pending",IF(H14=4,"4 of 5, depth pending","Low overlap")),IF(N14>=4,"Real overlap",IF(N14>=2,"Partial overlap","Low overlap"))) -> Full presence, depth pending
A15: M Shorts | B15: 4 | C15: Y | D15: Y | E15: Y | F15: N | G15: Y | H15: =COUNTIF(C15:G15,"Y")+COUNTIF(C15:G15,"P") -> 4 | N15: =IF(COUNT(I15:M15)=0,"",COUNTIF(I15:M15,">="&$F$3)) | O15: =IF(N15="",IF(H15>=5,"Full presence, depth pending",IF(H15=4,"4 of 5, depth pending","Low overlap")),IF(N15>=4,"Real overlap",IF(N15>=2,"Partial overlap","Low overlap"))) -> 4 of 5, depth pending
A16: M Pants | B16: 4 | C16: Y | D16: Y | E16: Y | F16: N | G16: Y | H16: =COUNTIF(C16:G16,"Y")+COUNTIF(C16:G16,"P") -> 4 | N16: =IF(COUNT(I16:M16)=0,"",COUNTIF(I16:M16,">="&$F$3)) | O16: =IF(N16="",IF(H16>=5,"Full presence, depth pending",IF(H16=4,"4 of 5, depth pending","Low overlap")),IF(N16>=4,"Real overlap",IF(N16>=2,"Partial overlap","Low overlap"))) -> 4 of 5, depth pending
A17: M SS / LS Tops | B17: 4 | C17: Y | D17: Y | E17: Y | F17: N | G17: Y | H17: =COUNTIF(C17:G17,"Y")+COUNTIF(C17:G17,"P") -> 4 | N17: =IF(COUNT(I17:M17)=0,"",COUNTIF(I17:M17,">="&$F$3)) | O17: =IF(N17="",IF(H17>=5,"Full presence, depth pending",IF(H17=4,"4 of 5, depth pending","Low overlap")),IF(N17>=4,"Real overlap",IF(N17>=2,"Partial overlap","Low overlap"))) -> 4 of 5, depth pending
... A22: Footwear | B22: 5 | C22: Y | D22: Y | E22: Y | F22: N | G22: N | H22: =COUNTIF(C22:G22,"Y")+COUNTIF(C22:G22,"P") -> 3 | N22: =IF(COUNT(I22:M22)=0,"",COUNTIF(I22:M22,">="&$F$3)) | O22: =IF(N22="",IF(H22>=5,"Full presence, depth pending",IF(H22=4,"4 of 5, depth pending","Low overlap")),IF(N22>=4,"Real overlap",IF(N22>=2,"Partial overlap","Low overlap"))) -> Low overlap
A24: Source: site navigation for all five brands, captured 30 Sep 2026. Athleta shows only top-level groups (Bottoms, Tops, Jackets, Bras, Dresses); subcategories marked P until the first crawl confirms them.

Sheet Fabric_Normalization
A1: Brand | B1: Name as marketed | C1: Type | D1: Seen where | E1: Fiber content (shell) | F1: Primary fiber | G1: Elastane % | H1: Handfeel claim | I1: Compression / support claim | J1: Other claims | K1: Status | L1: Source
A2: lululemon | B2: Nulu | C2: Fabric | D2: Yoga & Pilates story (homepage) | K2: Name seen; capture composition | L2: shop.lululemon.com, 30 Sep 2026
A3: lululemon | B3: Luon | C3: Fabric | D3: Define jacket feature (homepage) | K3: Name seen; capture composition | L3: shop.lululemon.com, 30 Sep 2026
A4: lululemon | B4: Smooth Spacer | C4: Fabric | D4: Homepage hero, new styles | H4: Soft, cool | K4: Name seen; capture composition | L4: shop.lululemon.com, 30 Sep 2026
A5: lululemon | B5: SuperLoft | C5: Fabric | D5: Steady State SuperLoft hoodie / pant | K5: Name seen; capture composition | L5: shop.lululemon.com, 30 Sep 2026
A6: lululemon | B6: Align | C6: Line | D6: Align Shop | K6: Line, not fabric. Link to fabric on crawl | L6: shop.lululemon.com nav
A7: lululemon | B7: Wunder Train | C7: Line | D7: To confirm on public site | K7: Line. Confirm on crawl | L7: Not yet observed on public site
A8: lululemon | B8: Fast and Free | C8: Line | D8: Run story, homepage | K8: Line. Confirm public fabric | L8: shop.lululemon.com, 30 Sep 2026
A9: lululemon | B9: Scuba | C9: Line | D9: Scuba Shop | K9: Line (fleece). Confirm fabric | L9: shop.lululemon.com nav
A10: Alo | B10: Airbrush | C10: Fabric | D10: Leggings page description | K10: Name seen; capture composition | L10: aloyoga.com/collections/womens-leggings, 30 Sep 2026
A11: Alo | B11: Airlift | C11: Fabric | D11: Leggings page description | K11: Name seen; capture composition | L11: aloyoga.com/collections/womens-leggings, 30 Sep 2026
A12: Alo | B12: Softsculpt | C12: Fabric | D12: Leggings page description | K12: Name seen; capture composition | L12: aloyoga.com/collections/womens-leggings, 30 Sep 2026
A13: Alo | B13: Accolade | C13: Line | D13: The Accolade Guide (nav) | K13: Line. Confirm fabric | L13: aloyoga.com nav
A14: Vuori | B14: BlissBlend Form | C14: Fabric | D14: FormRefined Legging PDP | E14: 74% Polyamide, 26% Elastane (liner 88% Polyester, 12% Elastane) | F14: Nylon/Polyamide | G14: 0.26 | H14: Soft | I14: Sculpting support (bonded waistband) | J14: 4-way stretch; Moisture wicking | K14: Verified from product page | L14: vuoriclothing.com FormRefined Legging PDP, 30 Sep 2026
A15: Vuori | B15: BlissBlend | C15: Fabric | D15: Collection page, homepage | H15: Soft | K15: Name seen; capture composition | L15: vuoriclothing.com, 30 Sep 2026
A16: Vuori | B16: DreamKnit | C16: Fabric | D16: Collection, homepage hero | H16: Soft | K16: Name seen; capture composition | L16: vuoriclothing.com, 30 Sep 2026
A17: Vuori | B17: Meta | C17: Fabric / line | D17: Collection pages | K17: Type unclear. Confirm | L17: vuoriclothing.com sitemap
A18: Vuori | B18: AllTheFeels / AllTheForm | C18: Fabric / line | D18: Collection pages; AllTheForm Bra | K18: Type unclear. Confirm | L18: vuoriclothing.com sitemap
A19: Vuori | B19: V1 Uplift | C19: Fabric / line | D19: Collection page | K19: Type unclear. Confirm | L19: vuoriclothing.com sitemap
A20: Vuori | B20: BreatheInterlock | C20: Fabric | D20: Collection page | K20: Name seen; capture composition | L20: vuoriclothing.com sitemap
A21: Vuori | B21: Halo | C21: Line | D21: Halo styles collection | K21: Line. Confirm fabric | L21: vuoriclothing.com sitemap
A22: Beyond Yoga | B22: Spacedye | C22: Fabric | D22: Spacedye Soft Shop | H22: Soft | K22: Name seen; capture composition | L22: beyondyoga.com, 30 Sep 2026
A23: Beyond Yoga | B23: LuxeFleece 2.0 | C23: Fabric | D23: LuxeFleece 2.0 Shop | K23: Name seen; capture composition | L23: beyondyoga.com, 30 Sep 2026
A24: Beyond Yoga | B24: glowzone | C24: Line | D24: HIIT + Train collection | K24: Type unclear. Confirm | L24: beyondyoga.com, 30 Sep 2026
A25: Athleta | B25: (not yet captured) | D25: Homepage showed no fabric names | K25: Capture on first crawl | L25: athleta.gap.com, 30 Sep 2026
A27: Seed sources for the rest: Vuori Fabric Guide (/pages/vuori-fabric-guide), Alo Men's Fabrication Guide (/pages/mens-fabrication-guide), Beyond Yoga Fabric Guide (/pages/fabric-guide) and Men's Fabric Guide. Composition comes from product pages, never from memory.

Sheet Wave1_Catalog
A1: capture_date | B1: brand | C1: source_url | D1: brand_style_code | E1: style_group_key | F1: style_name | G1: color_name | H1: style_color_id | I1: length_variant | J1: gender | K1: brand_category_path | L1: lulu_division | M1: lulu_class | N1: lulu_subclass | O1: activity | P1: brand_line | Q1: list_price_usd | R1: selling_price_usd | S1: markdown_pct | T1: on_promo_flag | U1: sitewide_promo_text | V1: is_new_flag | W1: size_range | X1: size_count | Y1: sizes_available | Z1: sizes_out_of_stock | AA1: extended_size_flag | AB1: inseam_in | AC1: rise | AD1: length_descriptor | AE1: fit_descriptor | AF1: waistband_type | AG1: pockets | AH1: front_seam | AI1: fabric_platform | AJ1: fiber_content_raw | AK1: primary_fiber | AL1: primary_fiber_pct | AM1: elastane_pct | AN1: recycled_flag | AO1: claimed_properties | AP1: colour_family | AQ1: print_or_solid | AR1: colors_for_style | AS1: rating | AT1: review_count | AU1: fit_score | AV1: first_seen_date | AW1: line_segment_inferred | AX1: extraction_method | AY1: qa_status
A2: 2026-09-30 | B2: Vuori | C2: https://vuoriclothing.com/products/womens-formrefined-legging-french-roast | D2: VW4494 | E2: vuori|vw4494 | F2: FormRefined Legging | G2: French Roast | H2: vuori|vw4494|french roast | I2: n/a | J2: Women | K2: Women > Leggings | L2: lulu Womens | M2: Womens Pants | N2: Womens Tights | O2: Unassigned | P2: FormRefined | Q2: 118 | R2: 118 | S2: =IF(OR(Q2="",Q2=0),"",1-R2/Q2) -> 0 | T2: N | V2: Y | W2: XXS-XXL | X2: 7 | AA2: Y | AC2: High | AD2: Ankle | AE2: Stretch to fit | AF2: Bonded | AG2: Not stated | AH2: No | AI2: Vuori BlissBlend Form | AJ2: 74% Polyamide, 26% Elastane (Shell), 88% Polyester, 12% Elastane (Liner) | AK2: Nylon/Polyamide | AL2: 0.74 | AM2: 0.26 | AN2: N | AO2: 4-way stretch; Moisture wicking | AP2: Brown | AQ2: Solid | AS2: 4.7 | AT2: 38 | AU2: 3.08 of 5 (leans runs small) | AV2: 2026-09-30 | AW2: Too early | AX2: Manual (test page) | AY2: Checked
A4: Row 2 is a worked example from a manual test of one product page. Paste crawler output (wave1_catalog.csv) starting at row 3, or replace row 2. Keep markdown_pct as a formula.

Sheet QA_Checks
A1: Wave 1 QA: fill rate on required fields and count reconciliation
A2: Fill rate threshold | C2: 0.9
A3: Count tolerance vs brand's own category count | C3: 0.05
A5: Required field | B5: Alo | C5: lululemon | D5: Vuori | E5: Athleta | F5: Beyond Yoga
A6: Rows captured | B6: =COUNTIF(Wave1_Catalog!$B$2:$B$5000,"Alo") -> 0 | C6: =COUNTIF(Wave1_Catalog!$B$2:$B$5000,"lululemon") -> 0 | D6: =COUNTIF(Wave1_Catalog!$B$2:$B$5000,"Vuori") -> 1 | E6: =COUNTIF(Wave1_Catalog!$B$2:$B$5000,"Athleta") -> 0 | F6: =COUNTIF(Wave1_Catalog!$B$2:$B$5000,"Beyond Yoga") -> 0
A7: source_url | B7: =IF(B$6=0,"",COUNTIFS(Wave1_Catalog!$B$2:$B$5000,"Alo",Wave1_Catalog!$C$2:$C$5000,"<>")/B$6) | C7: =IF(C$6=0,"",COUNTIFS(Wave1_Catalog!$B$2:$B$5000,"lululemon",Wave1_Catalog!$C$2:$C$5000,"<>")/C$6) | D7: =IF(D$6=0,"",COUNTIFS(Wave1_Catalog!$B$2:$B$5000,"Vuori",Wave1_Catalog!$C$2:$C$5000,"<>")/D$6) -> 1 | E7: =IF(E$6=0,"",COUNTIFS(Wave1_Catalog!$B$2:$B$5000,"Athleta",Wave1_Catalog!$C$2:$C$5000,"<>")/E$6) | F7: =IF(F$6=0,"",COUNTIFS(Wave1_Catalog!$B$2:$B$5000,"Beyond Yoga",Wave1_Catalog!$C$2:$C$5000,"<>")/F$6)
A8: brand_style_code | B8: =IF(B$6=0,"",COUNTIFS(Wave1_Catalog!$B$2:$B$5000,"Alo",Wave1_Catalog!$D$2:$D$5000,"<>")/B$6) | C8: =IF(C$6=0,"",COUNTIFS(Wave1_Catalog!$B$2:$B$5000,"lululemon",Wave1_Catalog!$D$2:$D$5000,"<>")/C$6) | D8: =IF(D$6=0,"",COUNTIFS(Wave1_Catalog!$B$2:$B$5000,"Vuori",Wave1_Catalog!$D$2:$D$5000,"<>")/D$6) -> 1 | E8: =IF(E$6=0,"",COUNTIFS(Wave1_Catalog!$B$2:$B$5000,"Athleta",Wave1_Catalog!$D$2:$D$5000,"<>")/E$6) | F8: =IF(F$6=0,"",COUNTIFS(Wave1_Catalog!$B$2:$B$5000,"Beyond Yoga",Wave1_Catalog!$D$2:$D$5000,"<>")/F$6)
A9: style_group_key | B9: =IF(B$6=0,"",COUNTIFS(Wave1_Catalog!$B$2:$B$5000,"Alo",Wave1_Catalog!$E$2:$E$5000,"<>")/B$6) | C9: =IF(C$6=0,"",COUNTIFS(Wave1_Catalog!$B$2:$B$5000,"lululemon",Wave1_Catalog!$E$2:$E$5000,"<>")/C$6) | D9: =IF(D$6=0,"",COUNTIFS(Wave1_Catalog!$B$2:$B$5000,"Vuori",Wave1_Catalog!$E$2:$E$5000,"<>")/D$6) -> 1 | E9: =IF(E$6=0,"",COUNTIFS(Wave1_Catalog!$B$2:$B$5000,"Athleta",Wave1_Catalog!$E$2:$E$5000,"<>")/E$6) | F9: =IF(F$6=0,"",COUNTIFS(Wave1_Catalog!$B$2:$B$5000,"Beyond Yoga",Wave1_Catalog!$E$2:$E$5000,"<>")/F$6)
A10: style_name | B10: =IF(B$6=0,"",COUNTIFS(Wave1_Catalog!$B$2:$B$5000,"Alo",Wave1_Catalog!$F$2:$F$5000,"<>")/B$6) | C10: =IF(C$6=0,"",COUNTIFS(Wave1_Catalog!$B$2:$B$5000,"lululemon",Wave1_Catalog!$F$2:$F$5000,"<>")/C$6) | D10: =IF(D$6=0,"",COUNTIFS(Wave1_Catalog!$B$2:$B$5000,"Vuori",Wave1_Catalog!$F$2:$F$5000,"<>")/D$6) -> 1 | E10: =IF(E$6=0,"",COUNTIFS(Wave1_Catalog!$B$2:$B$5000,"Athleta",Wave1_Catalog!$F$2:$F$5000,"<>")/E$6) | F10: =IF(F$6=0,"",COUNTIFS(Wave1_Catalog!$B$2:$B$5000,"Beyond Yoga",Wave1_Catalog!$F$2:$F$5000,"<>")/F$6)
A11: color_name | B11: =IF(B$6=0,"",COUNTIFS(Wave1_Catalog!$B$2:$B$5000,"Alo",Wave1_Catalog!$G$2:$G$5000,"<>")/B$6) | C11: =IF(C$6=0,"",COUNTIFS(Wave1_Catalog!$B$2:$B$5000,"lululemon",Wave1_Catalog!$G$2:$G$5000,"<>")/C$6) | D11: =IF(D$6=0,"",COUNTIFS(Wave1_Catalog!$B$2:$B$5000,"Vuori",Wave1_Catalog!$G$2:$G$5000,"<>")/D$6) -> 1 | E11: =IF(E$6=0,"",COUNTIFS(Wave1_Catalog!$B$2:$B$5000,"Athleta",Wave1_Catalog!$G$2:$G$5000,"<>")/E$6) | F11: =IF(F$6=0,"",COUNTIFS(Wave1_Catalog!$B$2:$B$5000,"Beyond Yoga",Wave1_Catalog!$G$2:$G$5000,"<>")/F$6)
A12: brand_category_path | B12: =IF(B$6=0,"",COUNTIFS(Wave1_Catalog!$B$2:$B$5000,"Alo",Wave1_Catalog!$K$2:$K$5000,"<>")/B$6) | C12: =IF(C$6=0,"",COUNTIFS(Wave1_Catalog!$B$2:$B$5000,"lululemon",Wave1_Catalog!$K$2:$K$5000,"<>")/C$6) | D12: =IF(D$6=0,"",COUNTIFS(Wave1_Catalog!$B$2:$B$5000,"Vuori",Wave1_Catalog!$K$2:$K$5000,"<>")/D$6) -> 1 | E12: =IF(E$6=0,"",COUNTIFS(Wave1_Catalog!$B$2:$B$5000,"Athleta",Wave1_Catalog!$K$2:$K$5000,"<>")/E$6) | F12: =IF(F$6=0,"",COUNTIFS(Wave1_Catalog!$B$2:$B$5000,"Beyond Yoga",Wave1_Catalog!$K$2:$K$5000,"<>")/F$6)
A13: brand_line | B13: =IF(B$6=0,"",COUNTIFS(Wave1_Catalog!$B$2:$B$5000,"Alo",Wave1_Catalog!$P$2:$P$5000,"<>")/B$6) | C13: =IF(C$6=0,"",COUNTIFS(Wave1_Catalog!$B$2:$B$5000,"lululemon",Wave1_Catalog!$P$2:$P$5000,"<>")/C$6) | D13: =IF(D$6=0,"",COUNTIFS(Wave1_Catalog!$B$2:$B$5000,"Vuori",Wave1_Catalog!$P$2:$P$5000,"<>")/D$6) -> 1 | E13: =IF(E$6=0,"",COUNTIFS(Wave1_Catalog!$B$2:$B$5000,"Athleta",Wave1_Catalog!$P$2:$P$5000,"<>")/E$6) | F13: =IF(F$6=0,"",COUNTIFS(Wave1_Catalog!$B$2:$B$5000,"Beyond Yoga",Wave1_Catalog!$P$2:$P$5000,"<>")/F$6)
A14: list_price_usd | B14: =IF(B$6=0,"",COUNTIFS(Wave1_Catalog!$B$2:$B$5000,"Alo",Wave1_Catalog!$Q$2:$Q$5000,"<>")/B$6) | C14: =IF(C$6=0,"",COUNTIFS(Wave1_Catalog!$B$2:$B$5000,"lululemon",Wave1_Catalog!$Q$2:$Q$5000,"<>")/C$6) | D14: =IF(D$6=0,"",COUNTIFS(Wave1_Catalog!$B$2:$B$5000,"Vuori",Wave1_Catalog!$Q$2:$Q$5000,"<>")/D$6) -> 1 | E14: =IF(E$6=0,"",COUNTIFS(Wave1_Catalog!$B$2:$B$5000,"Athleta",Wave1_Catalog!$Q$2:$Q$5000,"<>")/E$6) | F14: =IF(F$6=0,"",COUNTIFS(Wave1_Catalog!$B$2:$B$5000,"Beyond Yoga",Wave1_Catalog!$Q$2:$Q$5000,"<>")/F$6)
A15: selling_price_usd | B15: =IF(B$6=0,"",COUNTIFS(Wave1_Catalog!$B$2:$B$5000,"Alo",Wave1_Catalog!$R$2:$R$5000,"<>")/B$6) | C15: =IF(C$6=0,"",COUNTIFS(Wave1_Catalog!$B$2:$B$5000,"lululemon",Wave1_Catalog!$R$2:$R$5000,"<>")/C$6) | D15: =IF(D$6=0,"",COUNTIFS(Wave1_Catalog!$B$2:$B$5000,"Vuori",Wave1_Catalog!$R$2:$R$5000,"<>")/D$6) -> 1 | E15: =IF(E$6=0,"",COUNTIFS(Wave1_Catalog!$B$2:$B$5000,"Athleta",Wave1_Catalog!$R$2:$R$5000,"<>")/E$6) | F15: =IF(F$6=0,"",COUNTIFS(Wave1_Catalog!$B$2:$B$5000,"Beyond Yoga",Wave1_Catalog!$R$2:$R$5000,"<>")/F$6)
A16: on_promo_flag | B16: =IF(B$6=0,"",COUNTIFS(Wave1_Catalog!$B$2:$B$5000,"Alo",Wave1_Catalog!$T$2:$T$5000,"<>")/B$6) | C16: =IF(C$6=0,"",COUNTIFS(Wave1_Catalog!$B$2:$B$5000,"lululemon",Wave1_Catalog!$T$2:$T$5000,"<>")/C$6) | D16: =IF(D$6=0,"",COUNTIFS(Wave1_Catalog!$B$2:$B$5000,"Vuori",Wave1_Catalog!$T$2:$T$5000,"<>")/D$6) -> 1 | E16: =IF(E$6=0,"",COUNTIFS(Wave1_Catalog!$B$2:$B$5000,"Athleta",Wave1_Catalog!$T$2:$T$5000,"<>")/E$6) | F16: =IF(F$6=0,"",COUNTIFS(Wave1_Catalog!$B$2:$B$5000,"Beyond Yoga",Wave1_Catalog!$T$2:$T$5000,"<>")/F$6)
A17: is_new_flag | B17: =IF(B$6=0,"",COUNTIFS(Wave1_Catalog!$B$2:$B$5000,"Alo",Wave1_Catalog!$V$2:$V$5000,"<>")/B$6) | C17: =IF(C$6=0,"",COUNTIFS(Wave1_Catalog!$B$2:$B$5000,"lululemon",Wave1_Catalog!$V$2:$V$5000,"<>")/C$6) | D17: =IF(D$6=0,"",COUNTIFS(Wave1_Catalog!$B$2:$B$5000,"Vuori",Wave1_Catalog!$V$2:$V$5000,"<>")/D$6) -> 1 | E17: =IF(E$6=0,"",COUNTIFS(Wave1_Catalog!$B$2:$B$5000,"Athleta",Wave1_Catalog!$V$2:$V$5000,"<>")/E$6) | F17: =IF(F$6=0,"",COUNTIFS(Wave1_Catalog!$B$2:$B$5000,"Beyond Yoga",Wave1_Catalog!$V$2:$V$5000,"<>")/F$6)
A18: size_range | B18: =IF(B$6=0,"",COUNTIFS(Wave1_Catalog!$B$2:$B$5000,"Alo",Wave1_Catalog!$W$2:$W$5000,"<>")/B$6) | C18: =IF(C$6=0,"",COUNTIFS(Wave1_Catalog!$B$2:$B$5000,"lululemon",Wave1_Catalog!$W$2:$W$5000,"<>")/C$6) | D18: =IF(D$6=0,"",COUNTIFS(Wave1_Catalog!$B$2:$B$5000,"Vuori",Wave1_Catalog!$W$2:$W$5000,"<>")/D$6) -> 1 | E18: =IF(E$6=0,"",COUNTIFS(Wave1_Catalog!$B$2:$B$5000,"Athleta",Wave1_Catalog!$W$2:$W$5000,"<>")/E$6) | F18: =IF(F$6=0,"",COUNTIFS(Wave1_Catalog!$B$2:$B$5000,"Beyond Yoga",Wave1_Catalog!$W$2:$W$5000,"<>")/F$6)
A19: size_count | B19: =IF(B$6=0,"",COUNTIFS(Wave1_Catalog!$B$2:$B$5000,"Alo",Wave1_Catalog!$X$2:$X$5000,"<>")/B$6) | C19: =IF(C$6=0,"",COUNTIFS(Wave1_Catalog!$B$2:$B$5000,"lululemon",Wave1_Catalog!$X$2:$X$5000,"<>")/C$6) | D19: =IF(D$6=0,"",COUNTIFS(Wave1_Catalog!$B$2:$B$5000,"Vuori",Wave1_Catalog!$X$2:$X$5000,"<>")/D$6) -> 1 | E19: =IF(E$6=0,"",COUNTIFS(Wave1_Catalog!$B$2:$B$5000,"Athleta",Wave1_Catalog!$X$2:$X$5000,"<>")/E$6) | F19: =IF(F$6=0,"",COUNTIFS(Wave1_Catalog!$B$2:$B$5000,"Beyond Yoga",Wave1_Catalog!$X$2:$X$5000,"<>")/F$6)
A20: sizes_available | B20: =IF(B$6=0,"",COUNTIFS(Wave1_Catalog!$B$2:$B$5000,"Alo",Wave1_Catalog!$Y$2:$Y$5000,"<>")/B$6) | C20: =IF(C$6=0,"",COUNTIFS(Wave1_Catalog!$B$2:$B$5000,"lululemon",Wave1_Catalog!$Y$2:$Y$5000,"<>")/C$6) | D20: =IF(D$6=0,"",COUNTIFS(Wave1_Catalog!$B$2:$B$5000,"Vuori",Wave1_Catalog!$Y$2:$Y$5000,"<>")/D$6) -> 0 | E20: =IF(E$6=0,"",COUNTIFS(Wave1_Catalog!$B$2:$B$5000,"Athleta",Wave1_Catalog!$Y$2:$Y$5000,"<>")/E$6) | F20: =IF(F$6=0,"",COUNTIFS(Wave1_Catalog!$B$2:$B$5000,"Beyond Yoga",Wave1_Catalog!$Y$2:$Y$5000,"<>")/F$6)
A21: sizes_out_of_stock | B21: =IF(B$6=0,"",COUNTIFS(Wave1_Catalog!$B$2:$B$5000,"Alo",Wave1_Catalog!$Z$2:$Z$5000,"<>")/B$6) | C21: =IF(C$6=0,"",COUNTIFS(Wave1_Catalog!$B$2:$B$5000,"lululemon",Wave1_Catalog!$Z$2:$Z$5000,"<>")/C$6) | D21: =IF(D$6=0,"",COUNTIFS(Wave1_Catalog!$B$2:$B$5000,"Vuori",Wave1_Catalog!$Z$2:$Z$5000,"<>")/D$6) -> 0 | E21: =IF(E$6=0,"",COUNTIFS(Wave1_Catalog!$B$2:$B$5000,"Athleta",Wave1_Catalog!$Z$2:$Z$5000,"<>")/E$6) | F21: =IF(F$6=0,"",COUNTIFS(Wave1_Catalog!$B$2:$B$5000,"Beyond Yoga",Wave1_Catalog!$Z$2:$Z$5000,"<>")/F$6)
A22: extended_size_flag | B22: =IF(B$6=0,"",COUNTIFS(Wave1_Catalog!$B$2:$B$5000,"Alo",Wave1_Catalog!$AA$2:$AA$5000,"<>")/B$6) | C22: =IF(C$6=0,"",COUNTIFS(Wave1_Catalog!$B$2:$B$5000,"lululemon",Wave1_Catalog!$AA$2:$AA$5000,"<>")/C$6) | D22: =IF(D$6=0,"",COUNTIFS(Wave1_Catalog!$B$2:$B$5000,"Vuori",Wave1_Catalog!$AA$2:$AA$5000,"<>")/D$6) -> 1 | E22: =IF(E$6=0,"",COUNTIFS(Wave1_Catalog!$B$2:$B$5000,"Athleta",Wave1_Catalog!$AA$2:$AA$5000,"<>")/E$6) | F22: =IF(F$6=0,"",COUNTIFS(Wave1_Catalog!$B$2:$B$5000,"Beyond Yoga",Wave1_Catalog!$AA$2:$AA$5000,"<>")/F$6)
A23: rise | B23: =IF(B$6=0,"",COUNTIFS(Wave1_Catalog!$B$2:$B$5000,"Alo",Wave1_Catalog!$AC$2:$AC$5000,"<>")/B$6) | C23: =IF(C$6=0,"",COUNTIFS(Wave1_Catalog!$B$2:$B$5000,"lululemon",Wave1_Catalog!$AC$2:$AC$5000,"<>")/C$6) | D23: =IF(D$6=0,"",COUNTIFS(Wave1_Catalog!$B$2:$B$5000,"Vuori",Wave1_Catalog!$AC$2:$AC$5000,"<>")/D$6) -> 1 | E23: =IF(E$6=0,"",COUNTIFS(Wave1_Catalog!$B$2:$B$5000,"Athleta",Wave1_Catalog!$AC$2:$AC$5000,"<>")/E$6) | F23: =IF(F$6=0,"",COUNTIFS(Wave1_Catalog!$B$2:$B$5000,"Beyond Yoga",Wave1_Catalog!$AC$2:$AC$5000,"<>")/F$6)
A24: length_descriptor | B24: =IF(B$6=0,"",COUNTIFS(Wave1_Catalog!$B$2:$B$5000,"Alo",Wave1_Catalog!$AD$2:$AD$5000,"<>")/B$6) | C24: =IF(C$6=0,"",COUNTIFS(Wave1_Catalog!$B$2:$B$5000,"lululemon",Wave1_Catalog!$AD$2:$AD$5000,"<>")/C$6) | D24: =IF(D$6=0,"",COUNTIFS(Wave1_Catalog!$B$2:$B$5000,"Vuori",Wave1_Catalog!$AD$2:$AD$5000,"<>")/D$6) -> 1 | E24: =IF(E$6=0,"",COUNTIFS(Wave1_Catalog!$B$2:$B$5000,"Athleta",Wave1_Catalog!$AD$2:$AD$5000,"<>")/E$6) | F24: =IF(F$6=0,"",COUNTIFS(Wave1_Catalog!$B$2:$B$5000,"Beyond Yoga",Wave1_Catalog!$AD$2:$AD$5000,"<>")/F$6)
A25: fit_descriptor | B25: =IF(B$6=0,"",COUNTIFS(Wave1_Catalog!$B$2:$B$5000,"Alo",Wave1_Catalog!$AE$2:$AE$5000,"<>")/B$6) | C25: =IF(C$6=0,"",COUNTIFS(Wave1_Catalog!$B$2:$B$5000,"lululemon",Wave1_Catalog!$AE$2:$AE$5000,"<>")/C$6) | D25: =IF(D$6=0,"",COUNTIFS(Wave1_Catalog!$B$2:$B$5000,"Vuori",Wave1_Catalog!$AE$2:$AE$5000,"<>")/D$6) -> 1 | E25: =IF(E$6=0,"",COUNTIFS(Wave1_Catalog!$B$2:$B$5000,"Athleta",Wave1_Catalog!$AE$2:$AE$5000,"<>")/E$6) | F25: =IF(F$6=0,"",COUNTIFS(Wave1_Catalog!$B$2:$B$5000,"Beyond Yoga",Wave1_Catalog!$AE$2:$AE$5000,"<>")/F$6)
A26: pockets | B26: =IF(B$6=0,"",COUNTIFS(Wave1_Catalog!$B$2:$B$5000,"Alo",Wave1_Catalog!$AG$2:$AG$5000,"<>")/B$6) | C26: =IF(C$6=0,"",COUNTIFS(Wave1_Catalog!$B$2:$B$5000,"lululemon",Wave1_Catalog!$AG$2:$AG$5000,"<>")/C$6) | D26: =IF(D$6=0,"",COUNTIFS(Wave1_Catalog!$B$2:$B$5000,"Vuori",Wave1_Catalog!$AG$2:$AG$5000,"<>")/D$6) -> 1 | E26: =IF(E$6=0,"",COUNTIFS(Wave1_Catalog!$B$2:$B$5000,"Athleta",Wave1_Catalog!$AG$2:$AG$5000,"<>")/E$6) | F26: =IF(F$6=0,"",COUNTIFS(Wave1_Catalog!$B$2:$B$5000,"Beyond Yoga",Wave1_Catalog!$AG$2:$AG$5000,"<>")/F$6)
A27: fabric_platform | B27: =IF(B$6=0,"",COUNTIFS(Wave1_Catalog!$B$2:$B$5000,"Alo",Wave1_Catalog!$AI$2:$AI$5000,"<>")/B$6) | C27: =IF(C$6=0,"",COUNTIFS(Wave1_Catalog!$B$2:$B$5000,"lululemon",Wave1_Catalog!$AI$2:$AI$5000,"<>")/C$6) | D27: =IF(D$6=0,"",COUNTIFS(Wave1_Catalog!$B$2:$B$5000,"Vuori",Wave1_Catalog!$AI$2:$AI$5000,"<>")/D$6) -> 1 | E27: =IF(E$6=0,"",COUNTIFS(Wave1_Catalog!$B$2:$B$5000,"Athleta",Wave1_Catalog!$AI$2:$AI$5000,"<>")/E$6) | F27: =IF(F$6=0,"",COUNTIFS(Wave1_Catalog!$B$2:$B$5000,"Beyond Yoga",Wave1_Catalog!$AI$2:$AI$5000,"<>")/F$6)
A28: fiber_content_raw | B28: =IF(B$6=0,"",COUNTIFS(Wave1_Catalog!$B$2:$B$5000,"Alo",Wave1_Catalog!$AJ$2:$AJ$5000,"<>")/B$6) | C28: =IF(C$6=0,"",COUNTIFS(Wave1_Catalog!$B$2:$B$5000,"lululemon",Wave1_Catalog!$AJ$2:$AJ$5000,"<>")/C$6) | D28: =IF(D$6=0,"",COUNTIFS(Wave1_Catalog!$B$2:$B$5000,"Vuori",Wave1_Catalog!$AJ$2:$AJ$5000,"<>")/D$6) -> 1 | E28: =IF(E$6=0,"",COUNTIFS(Wave1_Catalog!$B$2:$B$5000,"Athleta",Wave1_Catalog!$AJ$2:$AJ$5000,"<>")/E$6) | F28: =IF(F$6=0,"",COUNTIFS(Wave1_Catalog!$B$2:$B$5000,"Beyond Yoga",Wave1_Catalog!$AJ$2:$AJ$5000,"<>")/F$6)
A29: primary_fiber | B29: =IF(B$6=0,"",COUNTIFS(Wave1_Catalog!$B$2:$B$5000,"Alo",Wave1_Catalog!$AK$2:$AK$5000,"<>")/B$6) | C29: =IF(C$6=0,"",COUNTIFS(Wave1_Catalog!$B$2:$B$5000,"lululemon",Wave1_Catalog!$AK$2:$AK$5000,"<>")/C$6) | D29: =IF(D$6=0,"",COUNTIFS(Wave1_Catalog!$B$2:$B$5000,"Vuori",Wave1_Catalog!$AK$2:$AK$5000,"<>")/D$6) -> 1 | E29: =IF(E$6=0,"",COUNTIFS(Wave1_Catalog!$B$2:$B$5000,"Athleta",Wave1_Catalog!$AK$2:$AK$5000,"<>")/E$6) | F29: =IF(F$6=0,"",COUNTIFS(Wave1_Catalog!$B$2:$B$5000,"Beyond Yoga",Wave1_Catalog!$AK$2:$AK$5000,"<>")/F$6)
A30: primary_fiber_pct | B30: =IF(B$6=0,"",COUNTIFS(Wave1_Catalog!$B$2:$B$5000,"Alo",Wave1_Catalog!$AL$2:$AL$5000,"<>")/B$6) | C30: =IF(C$6=0,"",COUNTIFS(Wave1_Catalog!$B$2:$B$5000,"lululemon",Wave1_Catalog!$AL$2:$AL$5000,"<>")/C$6) | D30: =IF(D$6=0,"",COUNTIFS(Wave1_Catalog!$B$2:$B$5000,"Vuori",Wave1_Catalog!$AL$2:$AL$5000,"<>")/D$6) -> 1 | E30: =IF(E$6=0,"",COUNTIFS(Wave1_Catalog!$B$2:$B$5000,"Athleta",Wave1_Catalog!$AL$2:$AL$5000,"<>")/E$6) | F30: =IF(F$6=0,"",COUNTIFS(Wave1_Catalog!$B$2:$B$5000,"Beyond Yoga",Wave1_Catalog!$AL$2:$AL$5000,"<>")/F$6)
A31: elastane_pct | B31: =IF(B$6=0,"",COUNTIFS(Wave1_Catalog!$B$2:$B$5000,"Alo",Wave1_Catalog!$AM$2:$AM$5000,"<>")/B$6) | C31: =IF(C$6=0,"",COUNTIFS(Wave1_Catalog!$B$2:$B$5000,"lululemon",Wave1_Catalog!$AM$2:$AM$5000,"<>")/C$6) | D31: =IF(D$6=0,"",COUNTIFS(Wave1_Catalog!$B$2:$B$5000,"Vuori",Wave1_Catalog!$AM$2:$AM$5000,"<>")/D$6) -> 1 | E31: =IF(E$6=0,"",COUNTIFS(Wave1_Catalog!$B$2:$B$5000,"Athleta",Wave1_Catalog!$AM$2:$AM$5000,"<>")/E$6) | F31: =IF(F$6=0,"",COUNTIFS(Wave1_Catalog!$B$2:$B$5000,"Beyond Yoga",Wave1_Catalog!$AM$2:$AM$5000,"<>")/F$6)
A32: claimed_properties | B32: =IF(B$6=0,"",COUNTIFS(Wave1_Catalog!$B$2:$B$5000,"Alo",Wave1_Catalog!$AO$2:$AO$5000,"<>")/B$6) | C32: =IF(C$6=0,"",COUNTIFS(Wave1_Catalog!$B$2:$B$5000,"lululemon",Wave1_Catalog!$AO$2:$AO$5000,"<>")/C$6) | D32: =IF(D$6=0,"",COUNTIFS(Wave1_Catalog!$B$2:$B$5000,"Vuori",Wave1_Catalog!$AO$2:$AO$5000,"<>")/D$6) -> 1 | E32: =IF(E$6=0,"",COUNTIFS(Wave1_Catalog!$B$2:$B$5000,"Athleta",Wave1_Catalog!$AO$2:$AO$5000,"<>")/E$6) | F32: =IF(F$6=0,"",COUNTIFS(Wave1_Catalog!$B$2:$B$5000,"Beyond Yoga",Wave1_Catalog!$AO$2:$AO$5000,"<>")/F$6)
A33: colour_family | B33: =IF(B$6=0,"",COUNTIFS(Wave1_Catalog!$B$2:$B$5000,"Alo",Wave1_Catalog!$AP$2:$AP$5000,"<>")/B$6) | C33: =IF(C$6=0,"",COUNTIFS(Wave1_Catalog!$B$2:$B$5000,"lululemon",Wave1_Catalog!$AP$2:$AP$5000,"<>")/C$6) | D33: =IF(D$6=0,"",COUNTIFS(Wave1_Catalog!$B$2:$B$5000,"Vuori",Wave1_Catalog!$AP$2:$AP$5000,"<>")/D$6) -> 1 | E33: =IF(E$6=0,"",COUNTIFS(Wave1_Catalog!$B$2:$B$5000,"Athleta",Wave1_Catalog!$AP$2:$AP$5000,"<>")/E$6) | F33: =IF(F$6=0,"",COUNTIFS(Wave1_Catalog!$B$2:$B$5000,"Beyond Yoga",Wave1_Catalog!$AP$2:$AP$5000,"<>")/F$6)
A34: print_or_solid | B34: =IF(B$6=0,"",COUNTIFS(Wave1_Catalog!$B$2:$B$5000,"Alo",Wave1_Catalog!$AQ$2:$AQ$5000,"<>")/B$6) | C34: =IF(C$6=0,"",COUNTIFS(Wave1_Catalog!$B$2:$B$5000,"lululemon",Wave1_Catalog!$AQ$2:$AQ$5000,"<>")/C$6) | D34: =IF(D$6=0,"",COUNTIFS(Wave1_Catalog!$B$2:$B$5000,"Vuori",Wave1_Catalog!$AQ$2:$AQ$5000,"<>")/D$6) -> 1 | E34: =IF(E$6=0,"",COUNTIFS(Wave1_Catalog!$B$2:$B$5000,"Athleta",Wave1_Catalog!$AQ$2:$AQ$5000,"<>")/E$6) | F34: =IF(F$6=0,"",COUNTIFS(Wave1_Catalog!$B$2:$B$5000,"Beyond Yoga",Wave1_Catalog!$AQ$2:$AQ$5000,"<>")/F$6)
A35: colors_for_style | B35: =IF(B$6=0,"",COUNTIFS(Wave1_Catalog!$B$2:$B$5000,"Alo",Wave1_Catalog!$AR$2:$AR$5000,"<>")/B$6) | C35: =IF(C$6=0,"",COUNTIFS(Wave1_Catalog!$B$2:$B$5000,"lululemon",Wave1_Catalog!$AR$2:$AR$5000,"<>")/C$6) | D35: =IF(D$6=0,"",COUNTIFS(Wave1_Catalog!$B$2:$B$5000,"Vuori",Wave1_Catalog!$AR$2:$AR$5000,"<>")/D$6) -> 0 | E35: =IF(E$6=0,"",COUNTIFS(Wave1_Catalog!$B$2:$B$5000,"Athleta",Wave1_Catalog!$AR$2:$AR$5000,"<>")/E$6) | F35: =IF(F$6=0,"",COUNTIFS(Wave1_Catalog!$B$2:$B$5000,"Beyond Yoga",Wave1_Catalog!$AR$2:$AR$5000,"<>")/F$6)
A37: Fields below threshold | B37: =IF(B$6=0,"",COUNTIF(B7:B35,"<"&$C$2)) | C37: =IF(C$6=0,"",COUNTIF(C7:C35,"<"&$C$2)) | D37: =IF(D$6=0,"",COUNTIF(D7:D35,"<"&$C$2)) -> 3 | E37: =IF(E$6=0,"",COUNTIF(E7:E35,"<"&$C$2)) | F37: =IF(F$6=0,"",COUNTIF(F7:F35,"<"&$C$2))
A39: Unique styles captured | G39: Enter distinct brand_style_code count from crawler run_summary.json
A40: Brand's own category count | G40: Product count shown on the brand's leggings page (crawler logs it when visible)
A41: Count gap | B41: =IF(OR(B40="",B40=0,B39=""),"",B39/B40-1) | C41: =IF(OR(C40="",C40=0,C39=""),"",C39/C40-1) | D41: =IF(OR(D40="",D40=0,D39=""),"",D39/D40-1) | E41: =IF(OR(E40="",E40=0,E39=""),"",E39/E40-1) | F41: =IF(OR(F40="",F40=0,F39=""),"",F39/F40-1)
A42: Wave 1 pass? | B42: =IF(OR(B$6=0,B41=""),"Pending",IF(AND(B37=0,ABS(B41)<=$C$3),"PASS","FAIL")) -> Pending | C42: =IF(OR(C$6=0,C41=""),"Pending",IF(AND(C37=0,ABS(C41)<=$C$3),"PASS","FAIL")) -> Pending | D42: =IF(OR(D$6=0,D41=""),"Pending",IF(AND(D37=0,ABS(D41)<=$C$3),"PASS","FAIL")) -> Pending | E42: =IF(OR(E$6=0,E41=""),"Pending",IF(AND(E37=0,ABS(E41)<=$C$3),"PASS","FAIL")) -> Pending | F42: =IF(OR(F$6=0,F41=""),"Pending",IF(AND(F37=0,ABS(F41)<=$C$3),"PASS","FAIL")) -> Pending
A44: Note: brand category counts often count style-colors or include sets. Record what the brand's number counts before judging the gap.

Sheet Source_Log
A1: Brand | B1: Home URL | C1: Platform | D1: Product URL pattern | E1: Product unit per URL | F1: Category page loads products without a browser? | G1: Structured product data | H1: Wave 1 seed URLs | I1: Observed 30 Sep 2026 | J1: Notes
A2: Alo | B2: https://www.aloyoga.com/ | C2: Shopify (confirmed by page tags) | D2: /products/<handle> | E2: To confirm on crawl | F2: No (grid loads by script) | G2: Shopify product JSON expected at /products/<handle>.json; confirm | H2: https://www.aloyoga.com/collections/womens-leggings | I2: Free shipping and returns banner. Fabric names Airbrush, Airlift, Softsculpt on leggings page.
A3: lululemon | B3: https://shop.lululemon.com/ | C3: Custom (Next.js) | D3: /p/<slug>/<id>?color=<code> | E3: One style; color by parameter; lengths as separate styles | F3: Partly (homepage carousels load) | G3: schema.org data on product page expected; confirm | H3: https://shop.lululemon.com/c/women-leggings/n1udsq ; https://shop.lululemon.com/c/women-capris/n1ml6n | I3: 'We Made Too Much' is the markdown section. New styles weekly (Tuesday). | J3: Public site only
A4: Vuori | B4: https://vuoriclothing.com/ | C4: Shopify (images on cdn.shopify.com) | D4: /products/<style>-<color> | E4: One style-color | F4: No (grid loads by script) | G4: Product page renders full detail without a browser (tested) | H4: https://vuoriclothing.com/collections/womens-leggings | I4: Free shipping over $75. Sitemap page lists every collection. Fabric guide at /pages/vuori-fabric-guide.
A5: Athleta | B5: https://athleta.gap.com/ | C5: Gap Inc. shared platform | D5: /browse/product.do?pid=<id> (to confirm) | E5: To confirm on crawl | F5: To confirm | G5: To confirm | H5: https://athleta.gap.com/browse/category.do?cid=1025878 | I5: Friends & Family: 30% off everything. Prices this week are promotional. Women and Girls only.
A6: Beyond Yoga | B6: https://beyondyoga.com/ | C6: Shopify (confirmed by page tags) | D6: /products/<style>-<color>-<code> | E6: One style-color | F6: Partly (sizes shown in new-arrival tiles) | G6: Shopify product JSON expected at /products/<handle>.json; confirm | H6: https://beyondyoga.com/collections/leggings ; https://beyondyoga.com/collections/pedal-pushers-capris | I6: SMS sign-up 20% off first order. Men's labeled NEW. Maternity, toddler, extended sizes 1X-4X.
